Workbook

Sheet P4G
A1: PLACA M5Q - 816 | E1: CAJAS
N2: MARGEN | P2: =E52/F16 -> 0.090366193
A3: COMPRA | J3: =485*5.5 -> 2667.5
A4: FECHA | B4: EMBARCACION | C4: PRODUCTO | D4: KILOS | E4: PRECIO | F4: TOTAL
A5: 46387 | B5: VIRGEN MARIA | C5: 1° | D5: 1867 | E5: 1.7 | F5: =ROUNDDOWN(D5*E5,0) -> 3173
A6: 46387 | B6: JUAN CARLOS | C6: 1° | D6: 6645 | E6: 1.5 | F6: =ROUNDDOWN(D6*E6,0) -> 9967
A7: 46387 | B7: TENIENTE GALVEZ | C7: 1° | D7: 5350 | E7: 1.5 | F7: =ROUNDDOWN(D7*E7,0) -> 8025
D8: =SUM(D5:D7) -> 13862 | F8: =SUM(F5:F7) -> 21165 | G8: (2) | J8: =F8*-1 -> -21165
A11: VENTA
A12: FECHA | B12: LUGAR | C12: PRODUCTO | D12: KILOS | E12: PRECIO | F12: TOTAL
A13: 46025 | B13: EL MAYOR | C13: POTA | D13: 5520.6 | E13: 2.4 | F13: =D13*E13 -> 13249.44
A14: 46025 | B14: EL MAYOR | C14: POTA | D14: 9596.2 | E14: 2.2 | F14: =D14*E14 -> 21111.64
F15: =D15*E15 -> 0 | J15: =F15 -> 0
A16: TOTAL VENTA | D16: =SUM(D13:D14) -> 15116.8 | F16: =SUM(F13:F14) -> 34361.08 | G16: (1) | J16: =SUM(J15) -> 0
A19: RENDIMIENTO | D19: =+D16-D8 -> 1254.8 | H19: UTILIDAD BRUTA | J19: =J16+J8 -> -21165 | L19: =J19/J16 -> #DIV/0!
C22: GASTOS MUELLE
C23: DETALLE | D23: IMPORTE
C24: FACTURACION | D24: 550
C25: PERSONAL 6.5 TN*90 | D25: 1215
C26: PESADOR | D26: 300
C27: APOYO | D27: 300
C28: AGUA | D28: 135
C29: CLOROX | D29: 30
C30: HIELO 2 TN*120 | D30: 720 | H30: 3300
C31: FLETE | D31: 3600 | H31: =H30/2 -> 1650 | I31: 1650
C32: OTROS | D32: 50 | H32: =H31*18% -> 297
C33: TOTAL | D33: =SUM(D24:D32) -> 6900 | E33: (3)
J34: =D31*-1 -> -3600
H35: UTILIDAD OPERATIVA | J35: =J34+J19 -> -24765 | L35: =J35/J16 -> #DIV/0!
C36: GASTOS ADMINISTRATIVO
C37: FACTURACION (0.1) | D37: =ROUNDDOWN(D16*0.1,0) -> 1511
C38: PESADOR | D38: 210
C39: GAST. FINANCIEROS | D39: =IF(F16<50000,50,IF(F16<100000,100,150)) -> 50
C40: OTROS GASTOS | D40: 150
C41: CERTIFICADO | D41: 90
C42: LIQUIDACION | D42: =ROUNDDOWN(D16*0.001,0)*10 -> 150
C43: IMPUESTO RENTA | D43: =ROUNDDOWN(0.03*F16,0) -> 1030 | J43: =D44 -> 3191
C44: TOTAL | D44: =ROUNDDOWN(SUM(D37:D43),0) -> 3191 | E44: (4) | H44: UT. ANTES DE REPARTO | J44: =J35+J43 -> -21574 | L44: =J44/J16 -> #DIV/0!
H45: UTILIDAD DE TERCEROS | J45: =J44*0.3*-1 -> 6472.2
C47: RESUMEN
...

Sheet CDP TRIBUTARIOS
B3: LIQUIDACION DE COMPRA SUSTENTADAS
B4: 1 | C4: 59000
B5: 2
B6: 3
B7: 4
B8: TOTAL LIQUIDACIONES DE COMPRAS | C8: =SUM(C4:C7) -> 59000
B9: IMPORTE REFERENTE | C9: =P4G!F16/1.04 -> 33039.5
B12: FACTURAS DE TRANSPORTE
B13: 1 | C13: 1622.5
B14: 2
B15: TOTAL DE FACTURAS | C15: =SUM(C13:C14) -> 1622.5
B16: IMPORTE REFERENTE | C16: =P4G!D31 -> 3600
B19: FACTURAS DE HIELO
B20: 1 | C20: 0
B21: 2 | C21: 0
B22: TOTAL FACTURAS | C22: =SUM(C20:C21) -> 0

Sheet EEFF SUNAT
B3: ESTADO DE RESULTADO CONTABLES /TRIBUTARIOS
E5: SUNAT | I5: REAL
B6: VENTAS - INGRESOS | E6: =P4G!F16 -> 34361.08 | J6: =P4G!F16 -> 34361.08
B8: COSTO DE VENTAS (LIQ) | E8: ='CDP TRIBUTARIOS'!C8 -> 59000 | J8: =P4G!F8 -> 21165
B10: UTILIDAD BRUTA | E10: =E6-E8 -> -24638.92 | G10: =E10/E6 -> -0.71705895 | I10: =J10/J6 -> 0.38404148 | J10: =J6-J8 -> 13196.08
B12: GASTOS ADMINISTRATIVOS | E12: ='CDP TRIBUTARIOS'!C15+'CDP TRIBUTARIOS'!C22+'CDP TRIBUTARIOS'!C22 -> 1622.5 | G12: AQUI SOLO | J12: =P4G!D33+P4G!D44 -> 10091
B13: GASTOS DE VENTAS | E13: 1000 | G13: TRASNPORTE
B14: GASTOS FINANCIEROS
B16: UTILIDAD ANTES DE IMPUESTOS | E16: =E10-E12 -> -26261.42 | G16: =E16/E6 -> -0.76427807 | I16: =J16/J6 -> 0.090366193 | J16: =J10-J12 -> 3105.08
B18: IMPUESTO A LA RENTA | E18: =E16*0.295 -> -7747.1189 | J18: =P4G!E56 -> 1552
B20: UTILIDAD NETA | E20: =E16-E18 -> -18514.301 | G20: =E20/E6 -> -0.53881604 | I20: =J20/J6 -> 0.045198812 | J20: =J16-J18 -> 1553.08

Sheet Copia de C5G - 826
A1: PLACA TET - TOD | I1: CAJAS | J1: 450
M2: MARGEN | O2: =E26/F16 -> -0.056594681
A3: COMPRA | I3: GASTOS MUELLE
A4: FECHA | B4: EMBARCACION | C4: PRODUCTO | D4: KILOS | E4: PRECIO | F4: TOTAL | I4: DETALLE | J4: IMPORTE
A5: 45786 | B5: DON HUMBERTO | C5: 1° | D5: 5746 | E5: 4.8 | F5: =ROUNDDOWN(D5*E5,0) -> 27580 | I5: PERSONAL | J5: 600
A6: 45786 | B6: DON HUMBERTO | C6: CATANA | D6: 120 | E6: 4 | F6: =ROUNDDOWN(D6*E6,0) -> 480 | I6: PESADOR | J6: 120
A7: 45786 | B7: DON HUMBERTO | C7: CATANA | D7: 190 | E7: 4 | F7: =ROUNDDOWN(D7*E7,0) -> 760 | I7: TINA | J7: 100
D8: =SUM(D5:D7) -> 6056 | F8: =SUM(F5:F7) -> 28820 | G8: (2) | I8: HIELO | J8: 600
I9: FLETE | J9: 3000
I10: TOTAL | J10: =SUM(J5:J9) -> 4420 | K10: (3)
A12: VENTA
A13: FECHA | B13: LUGAR | C13: PRODUCTO | D13: KILOS | E13: PRECIO | F13: TOTAL | I13: GASTOS ADMINISTRATIVO
A14: 45787 | B14: CORPESMAR | C14: POTA | D14: 6640.2 | E14: 5 | F14: =D14*E14 -> 33201 | I14: FACTURACION (0.1) | J14: =ROUNDDOWN(D16*0.1,0) -> 664
I15: PESADOR | J15: 70
A16: TOTAL VENTA | D16: =SUM(D14:D15) -> 6640.2 | F16: =SUM(F14:F15) -> 33201 | G16: (1) | I16: GAST. FINANCIEROS | J16: =IF(F16<50000,50,IF(F16<100000,100,150)) -> 50
I17: LIQUIDACION | J17: =ROUNDDOWN(D16*0.001,0)*10 -> 60
I18: IMPUESTO RENTA | J18: =ROUNDDOWN(0.03*F16,0) -> 996
A19: RENDIMIENTO | D19: =+D16-D8 -> 584.2 | I19: TOTAL | J19: =ROUNDDOWN(SUM(J14:J18),0) -> 1840 | K19: (4)
C21: RESUMEN
B22: (1) | C22: =+A12 -> VENTA | E22: =+F16 -> 33201
B23: (2) | C23: =+A3 -> COMPRA | E23: =-F8 -> -28820
B24: (3) | C24: =+I3 -> GASTOS MUELLE | E24: =-J10 -> -4420
B25: (4) | C25: =+I13 -> GASTOS ADMINISTRATIVO | E25: =-J19 -> -1840
C26: TOTAL | E26: =SUM(E22:E25) -> -1879
C28: 0.6 | D28: EMPRESA | E28: =ROUNDDOWN(E26*C28,0) -> -1127
C29: 0.4 | D29: DANIEL | E29: =ROUNDDOWN(E26*C29,0) -> -751
G32: OLAYA Y DE LA CONCHA
C38: PLACA M5U - 911 // MEGUI
C40: VENTA | D40: COMPRA | E40: RENDIMIENTO
C41: 13500.9 | D41: 11760 | E41: =C41-D41 -> 1740.9
