Workbook

Sheet CUADRE
A1: 🐙 BRIS MAR | C1: CUADRE DE PESCA | H1: PLACA: | K1: N° CAJAS: | N1: FECHA:
N2: MARGEN: | O2: =IFERROR(D46/F18,"")
A3: COMPRA (E.P. — En Planta)
A4: FECHA | B4: EMBARCACIÓN | C4: PRODUCTO | D4: KILOS | E4: PRECIO | F4: TOTAL
F5: =IF(D5="","",ROUNDDOWN(D5*E5,0))
F6: =IF(D6="","",ROUNDDOWN(D6*E6,0))
F7: =IF(D7="","",ROUNDDOWN(D7*E7,0))
F8: =IF(D8="","",ROUNDDOWN(D8*E8,0))
F9: =IF(D9="","",ROUNDDOWN(D9*E9,0))
A10: TOTAL COMPRA | D10: =IFERROR(SUM(D5:D9),0) -> 0 | F10: =IFERROR(SUM(F5:F9),0) -> 0 | G10: (2)
A12: VENTA
A13: FECHA | B13: LUGAR | C13: PRODUCTO | D13: KILOS | E13: PRECIO | F13: TOTAL
F14: =IF(D14="","",ROUNDDOWN(D14*E14,0))
F15: =IF(D15="","",ROUNDDOWN(D15*E15,0))
F16: =IF(D16="","",ROUNDDOWN(D16*E16,0))
F17: =IF(D17="","",ROUNDDOWN(D17*E17,0))
A18: TOTAL VENTA | D18: =IFERROR(SUM(D14:D17),0) -> 0 | F18: =IFERROR(SUM(F14:F17),0) -> 0 | G18: (1)
A20: RENDIMIENTO (kg venta − kg compra) | D20: =D18-D10 -> 0
A22: GASTOS DE MUELLE | I22: GASTOS ADMINISTRATIVOS
C23: DETALLE | D23: CANT./IMPORTE | E23: PRECIO UNIT. | F23: TOTAL | I23: DETALLE | J23: IMPORTE | K23: IMPORTE
C24: FACTURACIÓN | F24: =IF(D24="",0,D24) -> 0 | I24: FACTURACIÓN (0.1% venta) | J24: =IFERROR(ROUNDDOWN(F18*0.001*100,0),0) -> 0
C25: PERSONAL | F25: =IF(D25="",0,ROUNDDOWN(D25*E25,0)) -> 0 | I25: PESADOR
C26: PESADOR | F26: =IF(D26="",0,D26) -> 0 | I26: GAST. FINANCIEROS | J26: =IF(F18<50000,50,IF(F18<100000,100,150)) -> 50
C27: APOYO | F27: =IF(D27="",0,D27) -> 0 | I27: OTROS GASTOS
C28: AGUA | F28: =IF(D28="",0,D28) -> 0 | I28: CERTIFICADO SANITARIO
C29: CLOROX | F29: =IF(D29="",0,D29) -> 0 | I29: LIQUIDACIÓN | J29: =IFERROR(ROUNDDOWN(F18*0.001,0)*10,0) -> 0
C30: HIELO | F30: =IF(D30="",0,ROUNDDOWN(D30*E30,0)) -> 0 | I30: IMPUESTO RENTA (3%) | J30: =IFERROR(ROUNDDOWN(0.03*F18,0),0) -> 0
C31: FLETE | F31: =IF(D31="",0,ROUNDDOWN(D31*E31,0)) -> 0 | I31: CDP / LIQUIDACIÓN COMPRA
C32: OTROS | F32: =IF(D32="",0,D32) -> 0 | I32: GASTOS BANCO/FINANCIERO
C33: REINHIELADA | F33: =IF(D33="",0,ROUNDDOWN(D33*E33,0)) -> 0
C34: TOTAL GASTOS MUELLE | F34: =SUM(F24:F33) -> 0 | G34: (3) | I34: TOTAL GASTOS ADMIN. | J34: =IFERROR(ROUNDDOWN(SUM(J24:J33),0),0) -> 50 | K34: (4)
A36: UTILIDAD BRUTA (Venta − Compra) | D36: =F18-F10 -> 0 | E36: =IFERROR(F18-F10/F18,"")
A37: UTILIDAD OPERATIVA (− Gs. Muelle) | D37: =D36-F34 -> 0 | E37: =IFERROR(D36-F34/F18,"")
A38: UTILIDAD ANTES REPARTO (− Gs. Admin.) | D38: =D37-J34 -> -50 | E38: =IFERROR(D37-J34/F18,"")
A39: UTILIDAD DE TERCEROS (30%) | D39: =IFERROR(ROUNDDOWN(D38*0.3,0),0) -> -15
A41: RESUMEN FINANCIERO
A42: (1) VENTA | D42: =F18 -> 0
A43: (2) COMPRA | D43: =-F10 -> 0
A44: (3) GASTOS MUELLE | D44: =-F34 -> 0
A45: (4) GASTOS ADMIN. | D45: =-J34 -> -50
...

Sheet CDP TRIBUTARIOS
B1: CDP TRIBUTARIOS — DOCUMENTOS SUSTENTO
B3: LIQUIDACIONES DE COMPRA SUSTENTADAS
B4: 1
B5: 2
B6: 3
B7: 4
B8: 5
B9: TOTAL LIQUIDACIONES | C9: =SUM(C4:C8) -> 0
B10: IMPORTE REFERENTE (Venta/1.04) | C10: =IFERROR(CUADRE!F18/1.04,0) -> 0
B12: FACTURAS DE TRANSPORTE (FLETE)
B13: 1
B14: 2
B15: 3
B16: TOTAL FACTURAS FLETE | C16: =SUM(C13:C15) -> 0
B17: IMPORTE REFERENTE (Flete en cuadre) | C17: =IFERROR(CUADRE!F31,0) -> 0
B19: FACTURAS DE HIELO
B20: 1
B21: 2
B22: 3
B23: TOTAL FACTURAS HIELO | C23: =SUM(C20:C22) -> 0

Sheet EEFF SUNAT
B1: ESTADO DE RESULTADOS — CONTABLE / TRIBUTARIO
B3: CONCEPTO | D3: SUNAT (S/.) | F3: % SUNAT | H3: REAL (S/.) | I3: % REAL
B5: VENTAS / INGRESOS | D5: =CUADRE!F18 -> 0 | H5: =CUADRE!F18 -> 0
B7: COSTO DE VENTAS (liquidaciones) | D7: ='CDP TRIBUTARIOS'!C9 -> 0 | F7: =IFERROR(D7/D5,"") | H7: =CUADRE!F10 -> 0 | I7: =IFERROR(H7/H5,"")
B9: UTILIDAD BRUTA | D9: =D5-D7 -> 0 | F9: =IFERROR(D9/D5,"") | H9: =H5-H7 -> 0 | I9: =IFERROR(H9/H5,"")
B11: GASTOS ADMINISTRATIVOS | D11: ='CDP TRIBUTARIOS'!C16+'CDP TRIBUTARIOS'!C23 -> 0 | F11: =IFERROR(D11/D5,"") | H11: =CUADRE!F34+CUADRE!J34 -> 50 | I11: =IFERROR(H11/H5,"")
B12: GASTOS DE VENTAS (transporte) | D12: ='CDP TRIBUTARIOS'!C16 -> 0 | F12: =IFERROR(D12/D5,"") | H12: =CUADRE!F31 -> 0 | I12: =IFERROR(H12/H5,"")
B14: UTILIDAD ANTES DE IMPUESTOS | D14: =D9-D11-D12 -> 0 | F14: =IFERROR(D14/D5,"") | H14: =H9-H11 -> -50 | I14: =IFERROR(H14/H5,"")
B16: IMPUESTO A LA RENTA (29.5%) | D16: =D14*0.295 -> 0 | F16: =IFERROR(D16/D5,"") | H16: =CUADRE!J34 -> 50 | I16: =IFERROR(H16/H5,"")
B18: UTILIDAD NETA | D18: =D14-D16 -> 0 | F18: =IFERROR(D18/D5,"") | H18: =H14-H16 -> -100 | I18: =IFERROR(H18/H5,"")

Sheet INSTRUCCIONES
A1: 🐙 BRIS MAR — GUÍA DE USO DE LA PLANTILLA
A3: CÓMO LLENAR LA PLANTILLA
A4: 1. Ir a la hoja CUADRE
A5: 2. Llenar: PLACA (I1), N° CAJAS (L1), FECHA (O1)
A6: 3. Ingresar compras E.P.: fecha, embarcación, producto, kilos, precio (filas 5-9)
A7: 4. Ingresar ventas cuando lleguen: fecha, lugar, producto, kilos, precio (filas 14-17)
A8: 5. Ingresar gastos de muelle (filas 24-33): fijos = solo importe, variables = cantidad + precio/unidad
A9: 6. Gastos admin. (I24:J33): pesador, otros se llenan a mano. Facturación, financieros e imp. renta son automáticos
A10: 7. Ajustar porcentaje de reparto en B48 y B49 (default 50/50)
A12: CELDAS DE COLOR
A13: 🟡 AMARILLO SUAVE → Celda a llenar (input del usuario)
A14: 🟠 NARANJA → Calculado automáticamente
... A29: Solo abre el .xlsx recibido — todo estará calculado y formateado.
